<sdf version='1.6'>
  <model name='blastoise'>
    <link name='base_link'>
      <pose frame=''>0 0 0 0 -0 0</pose>
      <inertial>
        <pose frame=''>-1e-06 0.002826 -0.011618 0 -0 0</pose>
        <mass>55.507</mass>
        <inertia>
          <ixx>2.77034</ixx>
          <ixy>-1.21542e-07</ixy>
          <ixz>5.6891e-06</ixz>
          <iyy>3.07624</iyy>
          <iyz>0.0598599</iyz>
          <izz>2.69955</izz>
        </inertia>
      </inertial>
      <collision name='base_link_collision'>
        <pose frame=''>0 0 0 0 -0 0</pose>
        <geometry>
          <box>
            <size>0.65 0.0508 0.9906</size>
          </box>
        </geometry>
      </collision>
      <collision name='base_link_fixed_joint_lump__front_beam_collision_1'>
        <pose frame=''>0 0.2648 -0.42 0 -0 0</pose>
        <geometry>
          <box>
            <size>0.65 0.0508 0.0508</size>
          </box>
        </geometry>
      </collision>
      <visual name='base_link_visual'>
        <pose frame=''>0 0 0 0 -0 0</pose>
        <geometry>
          <box>
            <size>0.635 0.4826 0.9906</size>
          </box>
        </geometry>
      </visual>
      <visual name='base_link_fixed_joint_lump__front_beam_visual_1'>
        <pose frame=''>0 0.2648 -0.42 0 -0 0</pose>
        <geometry>
          <box>
            <size>0.65 0.0508 0.0508</size>
          </box>
        </geometry>
      </visual>
      <visual name='base_link_fixed_joint_lump__base_sonar_left_visual_2'>
        <pose frame=''>0.295 0.3032 -0.3692 -1.5707 -0 -0.78535</pose>
        <geometry>
          <mesh>
            <scale>0.001 0.001 0.001</scale>
            <uri>model://srl_robot_description/meshes/hc-sr04-ultrasonic-sensor.dae</uri>
          </mesh>
        </geometry>
      </visual>
      <visual name='base_link_fixed_joint_lump__base_sonar_right_visual_3'>
        <pose frame=''>-0.315 0.284 -0.3692 -1.5707 -0 0.78535</pose>
        <geometry>
          <mesh>
            <scale>0.001 0.001 0.001</scale>
            <uri>model://srl_robot_description/meshes/hc-sr04-ultrasonic-sensor.dae</uri>
          </mesh>
        </geometry>
      </visual>
      <visual name='base_link_fixed_joint_lump__mid_sonar_left_visual_4'>
        <pose frame=''>0.295 0.3032 0.088 -1.5707 -0 -0.78535</pose>
        <geometry>
          <mesh>
            <scale>0.001 0.001 0.001</scale>
            <uri>model://srl_robot_description/meshes/hc-sr04-ultrasonic-sensor.dae</uri>
          </mesh>
        </geometry>
      </visual>
      <visual name='base_link_fixed_joint_lump__mid_sonar_right_visual_5'>
        <pose frame=''>-0.315 0.284 0.088 -1.5707 -0 0.78535</pose>
        <geometry>
          <mesh>
            <scale>0.001 0.001 0.001</scale>
            <uri>model://srl_robot_description/meshes/hc-sr04-ultrasonic-sensor.dae</uri>
          </mesh>
        </geometry>
      </visual>
      <visual name='base_link_fixed_joint_lump__top_sonar_left_visual_6'>
        <pose frame=''>0.295 0.3032 0.5308 -1.5707 -0 -0.78535</pose>
        <geometry>
          <mesh>
            <scale>0.001 0.001 0.001</scale>
            <uri>model://srl_robot_description/meshes/hc-sr04-ultrasonic-sensor.dae</uri>
          </mesh>
        </geometry>
      </visual>
      <visual name='base_link_fixed_joint_lump__top_sonar_right_visual_7'>
        <pose frame=''>-0.315 0.284 0.5308 -1.5707 -0 0.78535</pose>
        <geometry>
          <mesh>
            <scale>0.001 0.001 0.001</scale>
            <uri>model://srl_robot_description/meshes/hc-sr04-ultrasonic-sensor.dae</uri>
          </mesh>
        </geometry>
      </visual>
      <visual name='base_link_fixed_joint_lump__base_laser_link_visual_8'>
        <pose frame=''>0 0.2848 -0.396 0 -0 0</pose>
        <geometry>
          <box>
            <size>0.05 0.05 0.06</size>
          </box>
        </geometry>
      </visual>
      <visual name='base_link_fixed_joint_lump__left_caster_plate_visual_9'>
        <pose frame=''>0.315 -0.22 -0.45 0 -0 0</pose>
        <geometry>
          <box>
            <size>0.1524 0.1524 0.0254</size>
          </box>
        </geometry>
      </visual>
      <visual name='base_link_fixed_joint_lump__right_caster_plate_visual_10'>
        <pose frame=''>-0.315 -0.22 -0.45 0 -0 0</pose>
        <geometry>
          <box>
            <size>0.1524 0.1524 0.0254</size>
          </box>
        </geometry>
      </visual>
    </link>
    <link name='left_caster'>
      <pose frame=''>0.35373 -0.2707 -0.45 0 -0 0</pose>
      <inertial>
        <pose frame=''>0 0 0 0 -0 0</pose>
        <mass>0.45</mass>
        <inertia>
          <ixx>1</ixx>
          <ixy>0</ixy>
          <ixz>0</ixz>
          <iyy>1</iyy>
          <iyz>0</iyz>
          <izz>1</izz>
        </inertia>
      </inertial>
      <visual name='left_caster_visual'>
        <pose frame=''>0.1155 0.16 0.0408 0 0 -1.5707</pose>
        <geometry>
          <mesh>
            <scale>1 1 1</scale>
            <uri>model://srl_robot_description/meshes/magni_caster.dae</uri>
          </mesh>
        </geometry>
      </visual>
    </link>
    <joint name='left_caster_joint' type='revolute'>
      <child>left_caster</child>
      <parent>base_link</parent>
      <axis>
        <xyz>0 0 1</xyz>
        <limit>
          <lower>-1e+16</lower>
          <upper>1e+16</upper>
        </limit>
        <dynamics>
          <spring_reference>0</spring_reference>
          <spring_stiffness>0</spring_stiffness>
        </dynamics>
        <use_parent_model_frame>1</use_parent_model_frame>
      </axis>
    </joint>
    <link name='left_wheel'>
      <pose frame=''>0.315 0.12 -0.45 0 -0 0</pose>
      <inertial>
        <pose frame=''>0 0 0 0 -0 0</pose>
        <mass>1</mass>
        <inertia>
          <ixx>1</ixx>
          <ixy>0</ixy>
          <ixz>0</ixz>
          <iyy>1</iyy>
          <iyz>0</iyz>
          <izz>1</izz>
        </inertia>
      </inertial>
      <visual name='left_wheel_visual'>
        <pose frame=''>-0.11 -0.16 0.055 0 0 -1.5707</pose>
        <geometry>
          <mesh>
            <scale>1 1 1</scale>
            <uri>model://srl_robot_description/meshes/magni_wheel.dae</uri>
          </mesh>
        </geometry>
      </visual>
    </link>
    <joint name='left_wheel_joint' type='revolute'>
      <child>left_wheel</child>
      <parent>base_link</parent>
      <axis>
        <xyz>1 0 0</xyz>
        <limit>
          <lower>-1e+16</lower>
          <upper>1e+16</upper>
        </limit>
        <dynamics>
          <spring_reference>0</spring_reference>
          <spring_stiffness>0</spring_stiffness>
        </dynamics>
        <use_parent_model_frame>1</use_parent_model_frame>
      </axis>
    </joint>
    <link name='right_caster'>
      <pose frame=''>-0.35373 -0.2707 -0.45 0 -0 0</pose>
      <inertial>
        <pose frame=''>0 0 0 0 -0 0</pose>
        <mass>0.45</mass>
        <inertia>
          <ixx>1</ixx>
          <ixy>0</ixy>
          <ixz>0</ixz>
          <iyy>1</iyy>
          <iyz>0</iyz>
          <izz>1</izz>
        </inertia>
      </inertial>
      <visual name='right_caster_visual'>
        <pose frame=''>0.1155 0.16 0.0408 0 0 -1.5707</pose>
        <geometry>
          <mesh>
            <scale>1 1 1</scale>
            <uri>model://srl_robot_description/meshes/magni_caster.dae</uri>
          </mesh>
        </geometry>
      </visual>
    </link>
    <joint name='right_caster_joint' type='revolute'>
      <child>right_caster</child>
      <parent>base_link</parent>
      <axis>
        <xyz>0 0 1</xyz>
        <limit>
          <lower>-1e+16</lower>
          <upper>1e+16</upper>
        </limit>
        <dynamics>
          <spring_reference>0</spring_reference>
          <spring_stiffness>0</spring_stiffness>
        </dynamics>
        <use_parent_model_frame>1</use_parent_model_frame>
      </axis>
    </joint>
    <link name='right_wheel'>
      <pose frame=''>-0.315 0.12 -0.45 0 -0 0</pose>
      <inertial>
        <pose frame=''>0 0 0 0 -0 0</pose>
        <mass>1</mass>
        <inertia>
          <ixx>1</ixx>
          <ixy>0</ixy>
          <ixz>0</ixz>
          <iyy>1</iyy>
          <iyz>0</iyz>
          <izz>1</izz>
        </inertia>
      </inertial>
      <visual name='right_wheel_visual'>
        <pose frame=''>0.11 0.16 0.055 0 -0 1.5707</pose>
        <geometry>
          <mesh>
            <scale>1 1 1</scale>
            <uri>model://srl_robot_description/meshes/magni_wheel.dae</uri>
          </mesh>
        </geometry>
      </visual>
    </link>
    <joint name='right_wheel_joint' type='revolute'>
      <child>right_wheel</child>
      <parent>base_link</parent>
      <axis>
        <xyz>1 0 0</xyz>
        <limit>
          <lower>-1e+16</lower>
          <upper>1e+16</upper>
        </limit>
        <dynamics>
          <spring_reference>0</spring_reference>
          <spring_stiffness>0</spring_stiffness>
        </dynamics>
        <use_parent_model_frame>1</use_parent_model_frame>
      </axis>
    </joint>
  </model>
</sdf>
