<robot name="blastoise">
  <link name="base_link">
   <visual> 
     <geometry>
       <box size="0.635 0.4826 0.9906" />
     </geometry>
     <material name="white">
        <color rgba="1 1 1 1"/>
     </material>
   </visual>
   <collision> 
     <geometry>
       <box size="0.650 0.4826 1.145" />
     </geometry>
   </collision>    
    <inertial>
       <origin xyz="0 0 -0.4" rpy="0 0 0"/>
       <mass value="54"/>
       <inertia ixx="0.004" ixy="0.0" ixz="0.0" iyy="0.004" iyz="0.0" izz="0.004"/>
    </inertial>
  </link>


  <link name="front_beam">
   <visual> 
    <geometry>
      <box size="0.650 0.0508 0.0508" />
      </geometry>
       <material name="grey">
        <color rgba="0.5 0.5 0.5 1"/>
       </material>
     </visual>
     <collision> 
       <geometry>
         <box size="0.650 0.0508 0.0508" />
       </geometry>
     </collision> 
        <inertial>
          <mass value="1" />
           <inertia ixx="0.004" ixy="0.0" ixz="0.0" iyy="0.3542" iyz="0.0" izz="0.3542" />
        </inertial>
  </link> 


  <link name="base_sonar_left"> 
    <visual>
     <geometry>
       <mesh filename="package://srl_robot_description/meshes/hc-sr04-ultrasonic-sensor.dae" scale="0.001 0.001 0.001"/>
     </geometry>
     <origin rpy="-1.5707 0 -0.78535"/>
     </visual>
        <inertial>
          <mass value="0.001" />
           <inertia ixx="0.0001" ixy="0" ixz="0" iyy=".0001" iyz="0" izz="0.0001" />
        </inertial>
 
  </link>
  
  <link name="base_sonar_right"> 
    <visual>
     <geometry>
      <mesh filename="package://srl_robot_description/meshes/hc-sr04-ultrasonic-sensor.dae" scale="0.001 0.001 0.001"/>
     </geometry>
     <origin rpy="-1.5707 0 0.78535"/>
     </visual>
        <inertial>
          <mass value="0.001" />
           <inertia ixx="0.0001" ixy="0" ixz="0" iyy=".0001" iyz="0" izz="0.0001" />
        </inertial>
  </link>

  <link name="mid_sonar_left"> 
    <visual>
     <geometry>
       <mesh filename="package://srl_robot_description/meshes/hc-sr04-ultrasonic-sensor.dae" scale="0.001 0.001 0.001"/>
     </geometry>
     <origin rpy="-1.5707 0 -0.78535"/>
     </visual>
        <inertial>
          <mass value="0.001" />
           <inertia ixx="0.0001" ixy="0" ixz="0" iyy=".0001" iyz="0" izz="0.0001" />
        </inertial>
  </link>
  
  <link name="mid_sonar_right"> 
    <visual>
     <geometry>
      <mesh filename="package://srl_robot_description/meshes/hc-sr04-ultrasonic-sensor.dae" scale="0.001 0.001 0.001"/>
     </geometry>
     <origin rpy="-1.5707 0 0.78535"/>
     </visual>
        <inertial>
          <mass value="0.001" />
           <inertia ixx="0.0001" ixy="0" ixz="0" iyy=".0001" iyz="0" izz="0.0001" />
        </inertial>
  </link>

  <link name="top_sonar_left"> 
    <visual>
     <geometry>
       <mesh filename="package://srl_robot_description/meshes/hc-sr04-ultrasonic-sensor.dae" scale="0.001 0.001 0.001"/>
     </geometry>
     <origin rpy="-1.5707 0 -0.78535"/>
     </visual>
        <inertial>
          <mass value="0.001" />
           <inertia ixx="0.0001" ixy="0" ixz="0" iyy=".0001" iyz="0" izz="0.0001" />
        </inertial>
  </link>
  
  <link name="top_sonar_right"> 
    <visual>
     <geometry>
      <mesh filename="package://srl_robot_description/meshes/hc-sr04-ultrasonic-sensor.dae" scale="0.001 0.001 0.001"/>
     </geometry>
     <origin rpy="-1.5707 0 0.78535"/>
     </visual>
        <inertial>
          <mass value="0.001" />
           <inertia ixx="0.0001" ixy="0" ixz="0" iyy=".0001" iyz="0" izz="0.0001" />
        </inertial>
  </link>

  <link name="left_wheel">
    <visual>
      <geometry>
        <mesh filename="package://srl_robot_description/meshes/magni_wheel.dae"/>
      </geometry>
      <origin rpy="0 0 -1.5707" xyz="-0.11 -0.16 0.055"/>
    </visual>
    <collision> 
        <origin rpy="0 -1.5707 0" xyz="0.0508 0 0"/>
        <geometry> 
<!--        <box size="0.2032 0.1371 0.2032"/> -->
        <cylinder length="0.0508" radius="0.1015"/>
        </geometry>
    </collision>
        <inertial>
          <mass value="1" />
           <inertia ixx="0.015" ixy="0" ixz="0" iyy="0.0375" iyz="0" izz="0.0375" /> -->
        </inertial>
   </link>

  <link name="right_wheel">
    <visual>
      <geometry>
        <mesh filename="package://srl_robot_description/meshes/magni_wheel.dae"/>
      </geometry>
      <origin rpy="0 0 1.5707" xyz="0.11 0.16 0.055"/>
    </visual>
    <collision> 
        <origin rpy="0 1.5707 0" xyz="-0.0508 0 0"/>
        <geometry> 
<!--        <box size="0.2032 0.1371 0.2032"/> -->
        <cylinder length="0.0508" radius="0.1015"/>
        </geometry>
    </collision>
        <inertial>
          <mass value="1" />
           <inertia ixx="0.015" ixy="0" ixz="0" iyy="0.0375" iyz="0" izz="0.0375" /> -->
        </inertial>
   </link>

  <link name="left_caster_plate">
   <visual>
      <geometry>
        <box size="0.1524 0.1524 0.0254"/>
      </geometry>
      <origin rpy="0 0 0" />
   </visual>
    <collision> 
        <geometry> 
        <box size="0.1524 0.1524 0.0254"/>
        </geometry>
    </collision>
        <inertial>
          <mass value="0.25" />
           <inertia ixx="0.0083" ixy="0" ixz="0" iyy="0.0083" iyz="0" izz="0.0083" />
        </inertial>
  </link>
 
  <link name="right_caster_plate">
   <visual>
      <geometry>
        <box size="0.1524 0.1524 0.0254"/>
      </geometry>
      <origin rpy="0 0 0" />
   </visual> 
    <collision> 
        <geometry> 
        <box size="0.1524 0.1524 0.0254"/>
        </geometry>
    </collision>
        <inertial>
          <mass value="0.25" />
           <inertia ixx="0.0083" ixy="0" ixz="0" iyy="0.0083" iyz="0" izz="0.0083" />
        </inertial>
  </link>

  <link name="left_caster"> 
    <visual>
      <geometry>
        <mesh filename="package://srl_robot_description/meshes/magni_caster.dae" />
      </geometry>
      <origin rpy="0 0 -1.5707" xyz="0.1155 0.16 0.045" />
      </visual>
    <collision> 
        <geometry> 
        <box size="0.08650 0.04600 0.130400"/>
        </geometry>
    </collision>

        <inertial>
          <mass value="0.45" />
           <inertia ixx="0.0083" ixy="0" ixz="0" iyy="0.0083" iyz="0" izz="0.0083" />
        </inertial>
  </link>
  
 <link name="right_caster"> 
    <visual>
      <geometry>
        <mesh filename="package://srl_robot_description/meshes/magni_caster.dae" />
      </geometry>
      <origin rpy="0 0 -1.5707" xyz="0.1155 0.16 0.045" />
      </visual>
    <collision> 
        <geometry> 
        <box size="0.08650 0.04600 0.130400"/>
        </geometry>
    </collision>
        <inertial>
          <mass value="0.45" />
           <inertia ixx="0.0083" ixy="0" ixz="0" iyy="0.0083" iyz="0" izz="0.0083" />

        </inertial>
  </link>

  <link name="base_laser_link">
    <visual>
      <geometry>
        <box size="0.05 0.05 0.06" />
      </geometry>
     <material name="green">
        <color rgba="0 1 0 1"/>
     </material>
    </visual>
    <collision> 
        <geometry> 
        <box size="0.05 0.05 0.06"/>
        </geometry>
    </collision>
    <inertial>
      <mass value="0.001" />
      <origin xyz="0 0 0" />
      <inertia ixx="0.0001" ixy="0.0" ixz="0.0"
        iyy="0.0001" iyz="0.0"
        izz="0.0001" />
    </inertial>
  </link>

<joint name="left_caster_plate_joint" type="fixed">
    <parent link="base_link" />
    <child link="left_caster_plate" />
    <origin xyz="0.3150 -0.22 -0.43" />
</joint>

<joint name="right_caster_plate_joint" type="fixed">
    <parent link="base_link" />
    <child link="right_caster_plate" />
    <origin xyz="-0.3150 -0.22 -0.43" />
</joint>

<joint name="front_beam_joint" type="fixed">
    <parent link="base_link" />
    <child link="front_beam" />
    <origin xyz="0 0.2648 -0.42" />
</joint>    

<joint name="left_caster_joint" type="continuous" >
    <parent link="left_caster_plate" />
    <child  link="left_caster" />
    <origin xyz="0.03873 -0.0507 -0.028" />
    <axis xyz="0 0 1" />
</joint> 
   
<joint name="right_caster_joint" type="continuous" >
    <parent link="right_caster_plate" />
    <child link="right_caster" />
    <origin xyz="-0.03873 -0.0507 -0.028" />
    <axis xyz="0 0 1" />
</joint>

<joint name="left_wheel_joint" type="continuous">
    <parent link="base_link" />
    <child link="left_wheel" />
    <origin xyz="0.3150 0.12 -0.475" />
    <axis xyz="1 0 0" />
</joint>

<joint name="right_wheel_joint" type="continuous">
    <parent link="base_link" />
    <child link="right_wheel" />
    <origin xyz="-0.3150 0.12 -0.475" />
    <axis xyz="1 0 0" />
    </joint>

<joint name="laser" type="fixed">
    <origin xyz="0 0.2848 -0.396" />
    <parent link="base_link" />
    <child link="base_laser_link" />
  </joint>

<joint name="base_sonar_left_joint" type="fixed">
    <parent link="front_beam" />
    <child link="base_sonar_left" />
    <origin xyz="0.2950 0.0384 0.0508" />
  </joint>

<joint name="base_sonar_right_joint" type="fixed">
    <parent link="front_beam" />
    <child link="base_sonar_right" />
    <origin xyz="-0.3150 .0192 0.0508" />
  </joint>


<joint name="mid_sonar_right_joint" type="fixed">
    <parent link="front_beam" />
    <child link="mid_sonar_right" />
    <origin xyz="-0.3150 .0192 0.508" />
  </joint>

<joint name="mid_sonar_left_joint" type="fixed">
    <parent link="front_beam" />
    <child link="mid_sonar_left" />
    <origin xyz="0.2950 0.0384 0.508" />
  </joint>

<joint name="top_sonar_right_joint" type="fixed">
    <parent link="front_beam" />
    <child link="top_sonar_right" />
    <origin xyz="-0.3150 .0192 0.9508" />
  </joint>

<joint name="top_sonar_left_joint" type="fixed">
    <parent link="front_beam" />
    <child link="top_sonar_left" />
    <origin xyz="0.2950 0.0384 0.9508" />
  </joint>

<gazebo>
  <plugin name="differential_drive_controller"
          filename="libgazebo_ros_diff_drive.so">
  <leftJoint>left_wheel_joint</leftJoint>
  <rightJoint>right_wheel_joint</rightJoint>
  <robotBaseFrame>base_link</robotBaseFrame>
  <wheelSeparation>0.4826</wheelSeparation>
  <wheelDiameter>0.15</wheelDiameter>
  <wheelTorque>20</wheelTorque>
  <wheelAcceleration>5</wheelAcceleration>
  <publishWheelJointState>true</publishWheelJointState>
  <commandTopic>cmd_vel</commandTopic>
  <odometryTopic>odom</odometryTopic>
  <odometryFrame>odom</odometryTopic>
  <legacyMode>false</true>
  </plugin>
</gazebo>

</robot>
